<?xml version="1.0" encoding="utf-8"?>
<!-- This URDF was automatically created by SolidWorks to URDF Exporter! Originally created by Stephen Brawner (brawner@gmail.com) 
     Commit Version: 1.6.0-1-g15f4949  Build Version: 1.6.7594.29634
     For more information, please see http://wiki.ros.org/sw_urdf_exporter -->
<robot
  name="xingtian_sym_model">
  <mujoco>
    <compiler
      meshdir = "../meshes/" 
      balanceinertia="true" 
      doscardvisual="false" />
  </mujoco>
  <link 
     name="world">
  </link>
  <joint name="world_joint" type="fixed">
    <origin
        xyz="0 0 0"
        rpy="0 0 0" />
     <parent link="world"/>
     <child link="base_link"/>
  </joint>
  <link
    name="base_link">
    <inertial>
      <origin
        xyz="-3.2632E-06 2.8538E-07 -0.00055079"
        rpy="0 0 0" />
      <mass
        value="26.135" />
      <inertia
        ixx="0.13317"
        ixy="2.3961E-06"
        ixz="-1.025E-05"
        iyy="0.96411"
        iyz="-5.4234E-11"
        izz="0.91536" />
    </inertial>
    <visual>
      <origin
        xyz="0 0 0"
        rpy="0 0 0" />
      <geometry>
        <mesh
          filename="../meshes/base_link.STL" />
      </geometry>
      <material
        name="">
        <color
          rgba="0.79608 0.82353 0.93725 1" />
      </material>
    </visual>
    <collision>
      <origin
        xyz="0 0 0"
        rpy="0 0 0" />
      <geometry>
        <mesh
          filename="../meshes/base_link.STL" />
      </geometry>
    </collision>
  </link>
  <link
    name="imu_link">
    <inertial>
      <origin
        xyz="5.5511E-17 0 -0.005"
        rpy="0 0 0" />
      <mass
        value="0.009" />
      <inertia
        ixx="7.5E-07"
        ixy="-1.1731E-22"
        ixz="-3.8933E-23"
        iyy="7.5E-07"
        iyz="1.4392E-22"
        izz="1.35E-06" />
    </inertial>
    <visual>
      <origin
        xyz="0 0 0"
        rpy="0 0 0" />
      <geometry>
        <mesh
          filename="../meshes/imu_link.STL" />
      </geometry>
      <material
        name="">
        <color
          rgba="1 1 1 1" />
      </material>
    </visual>
    <collision>
      <origin
        xyz="0 0 0"
        rpy="0 0 0" />
      <geometry>
        <mesh
          filename="../meshes/imu_link.STL" />
      </geometry>
    </collision>
  </link>
  <joint
    name="imu_joint"
    type="fixed">
    <origin
      xyz="0 0 0.0350983859380697"
      rpy="0 0 0" />
    <parent
      link="base_link" />
    <child
      link="imu_link" />
    <axis
      xyz="0 0 0" />
  </joint>
  <link name="camera_link">
    <visual>
      <origin
        xyz="0 0 0"
        rpy="0 0 0" />
        <geometry>
          <box size ="0.02 0.03 0.03" />
        </geometry>
      <material
        name="">
        <color
          rgba="1 1 1 1" />
      </material>
    </visual>
  </link>
  <joint
    name="camera_joint"
    type="fixed">
    <origin
      xyz="-0.25 0 0.13"
      rpy="0 0 3.1415926536" />
    <parent
      link="base_link" />
    <child
      link="camera_link" />
  </joint>
  <link name="laser_link">
    <visual>
      <origin
        xyz="0 0 0"
        rpy="0 0 0" />
         <geometry>
          <cylinder length ="0.06" radius = "0.04" />
        </geometry>
      <material
        name="red">
        <color
          rgba="1 1 1 1" />
      </material>
    </visual>
    </link>
  <joint
    name="laser_joint"
    type="fixed">
    <origin
      xyz="-0.2 0 0.15"
      rpy="0 0 3.1415926" />
    <parent
      link="base_link" />
    <child
      link="laser_link" />
  </joint>

  <link
    name="LF_hip">
    <inertial>
      <origin
        xyz="-0.038059 -0.0086135 -0.030705"
        rpy="0 0 0" />
      <mass
        value="0.25238" />
      <inertia
        ixx="0.00036585"
        ixy="5.8927E-06"
        ixz="-0.00028744"
        iyy="0.00068824"
        iyz="4.7541E-06"
        izz="0.00033564" />
    </inertial>
    <visual>
      <origin
        xyz="0 0 0"
        rpy="0 0 0" />
      <geometry>
        <mesh
          filename="../meshes/LF_hip.STL" />
      </geometry>
      <material
        name="">
        <color
          rgba="0.89804 0.91765 0.92941 1" />
      </material>
    </visual>
    <collision>
      <origin
        xyz="0 0 0"
        rpy="0 0 0" />
      <geometry>
        <mesh
          filename="../meshes/LF_hip.STL" />
      </geometry>
    </collision>
  </link>
  <joint
    name="LF_hip_joint"
    type="revolute">
    <origin
      xyz="0.20857 0.1825 -0.00081409"
      rpy="0 -2.18 0" />
    <parent
      link="base_link" />
    <child
      link="LF_hip" />
    <axis
      xyz="0 -1 0" />
    <limit
      lower="-3.14"
      upper="3.14"
      effort="10000"
      velocity="10" />
  </joint>
  <link
    name="LF_knee">
    <inertial>
      <origin
        xyz="0.04128 0.020491 -0.068957"
        rpy="0 0 0" />
      <mass
        value="0.10231" />
      <inertia
        ixx="0.0001662"
        ixy="-1.5377E-06"
        ixz="9.4256E-05"
        iyy="0.00022972"
        iyz="2.5686E-06"
        izz="6.5171E-05" />
    </inertial>
    <visual>
      <origin
        xyz="0 0 0"
        rpy="0 0 0" />
      <geometry>
        <mesh
          filename="../meshes/LF_knee.STL" />
      </geometry>
      <material
        name="">
        <color
          rgba="0.89804 0.91765 0.92941 1" />
      </material>
    </visual>
    <collision>
      <origin
        xyz="0 0 0"
        rpy="0 0 0" />
      <geometry>
        <mesh
          filename="../meshes/LF_knee.STL" />
      </geometry>
    </collision>
  </link>
  <joint
    name="LF_knee_joint"
    type="revolute">
    <origin
      xyz="-0.0806 -0.016 -0.11447"
      rpy="0 1.14 0" />
    <parent
      link="LF_hip" />
    <child
      link="LF_knee" />
    <axis
      xyz="0 -1 0" />
    <limit
      lower="-3.14"
      upper="3.14"
      effort="10000"
      velocity="10" />
  </joint>
  <link
    name="LF_wheel">
    <inertial>
      <origin
        xyz="-2.098E-14 0.039 1.4239E-14"
        rpy="0 0 0" />
      <mass
        value="3.5088" />
      <inertia
        ixx="0.0077572"
        ixy="1.7668E-18"
        ixz="5.8425E-19"
        iyy="0.013977"
        iyz="-4.9685E-18"
        izz="0.0077572" />
    </inertial>
    <visual>
      <origin
        xyz="0 0 0"
        rpy="0 0 0" />
      <geometry>
        <mesh
          filename="../meshes/LF_wheel.STL" />
      </geometry>
      <material
        name="">
        <color
          rgba="0.89804 0.91765 0.92941 1" />
      </material>
    </visual>
    <collision>
      <origin
        xyz="0 0 0"
        rpy="0 0 0" />
      <geometry>
        <mesh
          filename="../meshes/LF_wheel.STL" />
      </geometry>
    </collision>
  </link>
  <joint
    name="LF_wheel_joint"
    type="revolute">
    <origin
      xyz="0.071909 0.016 -0.12012"
      rpy="0 0 0" />
    <parent
      link="LF_knee" />
    <child
      link="LF_wheel" />
    <axis
      xyz="0 -1 0" />
    <limit  lower="-6.28318" upper="6.28318"
          effort="10000" velocity="50"/>
  </joint>
  <link
    name="LR_hip">
    <inertial>
      <origin
        xyz="0.038059 -0.0086135 -0.030705"
        rpy="0 0 0" />
      <mass
        value="0.25238" />
      <inertia
        ixx="0.00036585"
        ixy="-5.8927E-06"
        ixz="0.00028744"
        iyy="0.00068824"
        iyz="4.7541E-06"
        izz="0.00033564" />
    </inertial>
    <visual>
      <origin
        xyz="0 0 0"
        rpy="0 0 0" />
      <geometry>
        <mesh
          filename="../meshes/LR_hip.STL" />
      </geometry>
      <material
        name="">
        <color
          rgba="1 1 1 1" />
      </material>
    </visual>
    <collision>
      <origin
        xyz="0 0 0"
        rpy="0 0 0" />
      <geometry>
        <mesh
          filename="../meshes/LR_hip.STL" />
      </geometry>
    </collision>
  </link>
  <joint
    name="LR_hip_joint"
    type="revolute">
    <origin
      xyz="-0.20857 0.1825 -0.00081409"
      rpy="0 -2.18 0" />
    <parent
      link="base_link" />
    <child
      link="LR_hip" />
    <axis
      xyz="0 -1 0" />
    <limit
      lower="-3.14"
      upper="3.14"
      effort="10000"
      velocity="10" />
  </joint>
  <link
    name="LR_knee">
    <inertial>
      <origin
        xyz="-0.04128 0.020491 -0.068957"
        rpy="0 0 0" />
      <mass
        value="0.10231" />
      <inertia
        ixx="0.0001662"
        ixy="1.5377E-06"
        ixz="-9.4256E-05"
        iyy="0.00022972"
        iyz="2.5686E-06"
        izz="6.5171E-05" />
    </inertial>
    <visual>
      <origin
        xyz="0 0 0"
        rpy="0 0 0" />
      <geometry>
        <mesh
          filename="../meshes/LR_knee.STL" />
      </geometry>
      <material
        name="">
        <color
          rgba="0.89804 0.91765 0.92941 1" />
      </material>
    </visual>
    <collision>
      <origin
        xyz="0 0 0"
        rpy="0 0 0" />
      <geometry>
        <mesh
          filename="../meshes/LR_knee.STL" />
      </geometry>
    </collision>
  </link>
  <joint
    name="LR_knee_joint"
    type="revolute">
    <origin
      xyz="0.0806 -0.016 -0.11447"
      rpy="0 1.14 0" />
    <parent
      link="LR_hip" />
    <child
      link="LR_knee" />
    <axis
      xyz="0 -1 0" />
    <limit
      lower="-3.14"
      upper="3.14"
      effort="10000"
      velocity="10" />
  </joint>
  <link
    name="LR_wheel">
    <inertial>
      <origin
        xyz="5.5511E-17 0.039 -5.5511E-17"
        rpy="0 0 0" />
      <mass
        value="3.5088" />
      <inertia
        ixx="0.0077572"
        ixy="-1.4582E-18"
        ixz="1.2319E-19"
        iyy="0.013977"
        iyz="-3.7087E-18"
        izz="0.0077572" />
    </inertial>
    <visual>
      <origin
        xyz="0 0 0"
        rpy="0 0 0" />
      <geometry>
        <mesh
          filename="../meshes/LR_wheel.STL" />
      </geometry>
      <material
        name="">
        <color
          rgba="0.89804 0.91765 0.92941 1" />
      </material>
    </visual>
    <collision>
      <origin
        xyz="0 0 0"
        rpy="0 0 0" />
      <geometry>
        <mesh
          filename="../meshes/LR_wheel.STL" />
      </geometry>
    </collision>
  </link>
  <joint
    name="LR_wheel_joint"
    type="revolute">
    <origin
      xyz="-0.071909 0.016 -0.12012"
      rpy="0 0 0" />
    <parent
      link="LR_knee" />
    <child
      link="LR_wheel" />
    <axis
      xyz="0 -1 0" />
    <limit  lower="-6.28318" upper="6.28318"
          effort="10000" velocity="50"/>
  </joint>
  <link
    name="RR_hip">
    <inertial>
      <origin
        xyz="0.038059 0.0086135 -0.030705"
        rpy="0 0 0" />
      <mass
        value="0.25238" />
      <inertia
        ixx="0.00036585"
        ixy="5.8927E-06"
        ixz="0.00028744"
        iyy="0.00068824"
        iyz="-4.7541E-06"
        izz="0.00033564" />
    </inertial>
    <visual>
      <origin
        xyz="0 0 0"
        rpy="0 0 0" />
      <geometry>
        <mesh
          filename="../meshes/RR_hip.STL" />
      </geometry>
      <material
        name="">
        <color
          rgba="1 1 1 1" />
      </material>
    </visual>
    <collision>
      <origin
        xyz="0 0 0"
        rpy="0 0 0" />
      <geometry>
        <mesh
          filename="../meshes/RR_hip.STL" />
      </geometry>
    </collision>
  </link>
  <joint
    name="RR_hip_joint"
    type="revolute">
    <origin
      xyz="-0.20857 -0.1825 -0.00081409"
      rpy="0 -2.18 0" />
    <parent
      link="base_link" />
    <child
      link="RR_hip" />
    <axis
      xyz="0 -1 0" />
    <limit
      lower="-3.14"
      upper="3.14"
      effort="10000"
      velocity="10" />
  </joint>
  <link
    name="RR_knee">
    <inertial>
      <origin
        xyz="-0.04128 -0.020491 -0.068957"
        rpy="0 0 0" />
      <mass
        value="0.10231" />
      <inertia
        ixx="0.0001662"
        ixy="-1.5377E-06"
        ixz="-9.4256E-05"
        iyy="0.00022972"
        iyz="-2.5686E-06"
        izz="6.5171E-05" />
    </inertial>
    <visual>
      <origin
        xyz="0 0 0"
        rpy="0 0 0" />
      <geometry>
        <mesh
          filename="../meshes/RR_knee.STL" />
      </geometry>
      <material
        name="">
        <color
          rgba="1 1 1 1" />
      </material>
    </visual>
    <collision>
      <origin
        xyz="0 0 0"
        rpy="0 0 0" />
      <geometry>
        <mesh
          filename="../meshes/RR_knee.STL" />
      </geometry>
    </collision>
  </link>
  <joint
    name="RR_knee_joint"
    type="revolute">
    <origin
      xyz="0.0806 0.016 -0.11447"
      rpy="0 1.14 0" />
    <parent
      link="RR_hip" />
    <child
      link="RR_knee" />
    <axis
      xyz="0 -1 0" />
    <limit
      lower="-3.14"
      upper="3.14"
      effort="10000"
      velocity="10" />
  </joint>
  <link
    name="RR_wheel">
    <inertial>
      <origin
        xyz="-1.1102E-16 -0.039 5.5511E-17"
        rpy="0 0 0" />
      <mass
        value="3.5088" />
      <inertia
        ixx="0.0077572"
        ixy="1.8465E-18"
        ixz="2.0004E-19"
        iyy="0.013977"
        iyz="4.9949E-18"
        izz="0.0077572" />
    </inertial>
    <visual>
      <origin
        xyz="0 0 0"
        rpy="0 0 0" />
      <geometry>
        <mesh
          filename="../meshes/RR_wheel.STL" />
      </geometry>
      <material
        name="">
        <color
          rgba="0.89804 0.91765 0.92941 1" />
      </material>
    </visual>
    <collision>
      <origin
        xyz="0 0 0"
        rpy="0 0 0" />
      <geometry>
        <mesh
          filename="../meshes/RR_wheel.STL" />
      </geometry>
    </collision>
  </link>
  <joint
    name="RR_wheel_joint"
    type="revolute">
    <origin
      xyz="-0.071909 -0.016 -0.12012"
      rpy="0 0 0" />
    <parent
      link="RR_knee" />
    <child
      link="RR_wheel" />
    <axis
      xyz="0 -1 0" />
    <limit  lower="-6.28318" upper="6.28318"
          effort="10000" velocity="50"/>
  </joint>
  <link
    name="RF_hip">
    <inertial>
      <origin
        xyz="-0.038059 0.0086135 -0.030705"
        rpy="0 0 0" />
      <mass
        value="0.25238" />
      <inertia
        ixx="0.00036585"
        ixy="-5.8927E-06"
        ixz="-0.00028744"
        iyy="0.00068824"
        iyz="-4.7541E-06"
        izz="0.00033564" />
    </inertial>
    <visual>
      <origin
        xyz="0 0 0"
        rpy="0 0 0" />
      <geometry>
        <mesh
          filename="../meshes/RF_hip.STL" />
      </geometry>
      <material
        name="">
        <color
          rgba="1 1 1 1" />
      </material>
    </visual>
    <collision>
      <origin
        xyz="0 0 0"
        rpy="0 0 0" />
      <geometry>
        <mesh
          filename="../meshes/RF_hip.STL" />
      </geometry>
    </collision>
  </link>
  <joint
    name="RF_hip_joint"
    type="revolute">
    <origin
      xyz="0.20857 -0.1825 -0.00081409"
      rpy="0 -2.18 0" />
    <parent
      link="base_link" />
    <child
      link="RF_hip" />
    <axis
      xyz="0 -1 0" />
    <limit
      lower="-3.14"
      upper="3.14"
      effort="10000"
      velocity="10" />
  </joint>
  <link
    name="RF_knee">
    <inertial>
      <origin
        xyz="0.04128 -0.020491 -0.068957"
        rpy="0 0 0" />
      <mass
        value="0.10231" />
      <inertia
        ixx="0.0001662"
        ixy="1.5377E-06"
        ixz="9.4256E-05"
        iyy="0.00022972"
        iyz="-2.5686E-06"
        izz="6.5171E-05" />
    </inertial>
    <visual>
      <origin
        xyz="0 0 0"
        rpy="0 0 0" />
      <geometry>
        <mesh
          filename="../meshes/RF_knee.STL" />
      </geometry>
      <material
        name="">
        <color
          rgba="1 1 1 1" />
      </material>
    </visual>
    <collision>
      <origin
        xyz="0 0 0"
        rpy="0 0 0" />
      <geometry>
        <mesh
          filename="../meshes/RF_knee.STL" />
      </geometry>
    </collision>
  </link>
  <joint
    name="RF_knee_joint"
    type="revolute">
    <origin
      xyz="-0.0806 0.016 -0.11447"
      rpy="0 1.14 0" />
    <parent
      link="RF_hip" />
    <child
      link="RF_knee" />
    <axis
      xyz="0 -1 0" />
    <limit
      lower="-3.14"
      upper="3.14"
      effort="10000"
      velocity="10" />
  </joint>
  <link
    name="RF_wheel">
    <inertial>
      <origin
        xyz="9.7145E-17 -0.039 -2.7756E-17"
        rpy="0 0 0" />
      <mass
        value="3.5088" />
      <inertia
        ixx="0.0077572"
        ixy="-1.6998E-18"
        ixz="5.8425E-19"
        iyy="0.013977"
        iyz="4.905E-18"
        izz="0.0077572" />
    </inertial>
    <visual>
      <origin
        xyz="0 0 0"
        rpy="0 0 0" />
      <geometry>
        <mesh
          filename="../meshes/RF_wheel.STL" />
      </geometry>
      <material
        name="">
        <color
          rgba="0.89804 0.91765 0.92941 1" />
      </material>
    </visual>
    <collision>
      <origin
        xyz="0 0 0"
        rpy="0 0 0" />
      <geometry>
        <mesh
          filename="../meshes/RF_wheel.STL" />
      </geometry>
    </collision>
  </link>
  <joint
    name="RF_wheel_joint"
    type="revolute">
    <origin
      xyz="0.071909 -0.016 -0.12012"
      rpy="0 0 0" />
    <parent
      link="RF_knee" />
    <child
      link="RF_wheel" />
    <axis
      xyz="0 -1 0" />
    <limit  lower="-6.28318" upper="6.28318"
          effort="10000" velocity="50"/>
  </joint>
</robot>